<?xml version="1.0"?>
<robot xmlns:xacro="http://www.ros.org/wiki/xacro" name="rover">
    
    


    <link name="base">
        
    </link>
        
    <link name="body">
        <inertial>
            <origin xyz="0.0 0.0 0.0" rpy="0.0 0.0 0.0"/>
            <mass value="1.0"/>
            <inertia ixx="0.0" ixy="0.0" ixz="0.0" iyy="0.0" iyz="0.0" izz="0.0"/>
        </inertial>
        <visual name="">
            <origin xyz="0.0 0.0 0.0" rpy="0.0 0.0 0.0"/>
            <geometry>
                <box size="0.8 0.7 0.1"/>
            </geometry>
            <material name="">
                <color rgba="1.0 0.0 0.0 1.0"/>
                <texture filename=""/>
            </material>
        </visual>
        <collision>
            <origin xyz="0.0 0.0 0.0" rpy="0.0 0.0 0.0"/>
            <geometry>
                <box size="0.0 0.0 0.0"/>
            </geometry>
        </collision>
    </link>
    <joint name="world" type="revolute">
        <origin xyz="0.0 0.0 0.0" rpy="0.0 0.0 0.0"/>
        <parent link="base"/>
        <child link="body"/>
        <axis xyz="0.0 0.0 1.0"/>
        <limit lower="0.0" upper="0.0" effort="0.0" velocity="0.0"/>
        
    </joint>
    
    
    
     
    <!--front_right_wheel-->
    
    <xacro:macro name="wheel" params="name x y ">
    
        <link name="${name}_wheel">
            <inertial>
                <origin xyz="0.0 0.0 0.0" rpy="0.0 0.0 0.0"/>
                <mass value="0.5"/>
                <inertia ixx="0.0" ixy="0.0" ixz="0.0" iyy="0.0" iyz="0.0" izz="0.0"/>
            </inertial>
            <visual name="">
                <origin xyz="0.0 0.0 0.0" rpy="0.0 0.0 0.0"/>
                <geometry>
                    <cylinder radius="0.15" length="0.1"/>
                </geometry>
                <material name="black">
                    <color rgba="0 0.0 0.0 1.0"/>
                    <texture filename=""/>
                </material>
            </visual>
            <collision>
                <origin xyz="0.0 0.0 0.0" rpy="0.0 0.0 0.0"/>
                <geometry>
                    <box size="0.0 0.0 0.0"/>
                </geometry>
            </collision>
        </link>
        <joint name="${name}_wheel" type="continuous">
                <origin xyz="${x} ${y}  0.0" rpy="1.57 0 0"/>
                <parent link="body"/>
                <child link="${name}_wheel"/>
                <axis xyz="0.0 0.0 1.0"/>
        </joint>
            
    </xacro:macro>
    <xacro:wheel name="rear_right " x="0.25" y="0.4"/>
    <xacro:wheel name="front_right " x="-0.25" y="0.4"/>
    <xacro:wheel name="rear_left " x="0.25" y="-0.4"/>
    <xacro:wheel name="front_left " x="-0.25" y="-0.4"/>

</robot>